Workbook
Name HELLO: _xludf.LAMBDA(_xlpm.name, _xldudf_BOARDFLARE_EXEC("hello", _xlpm.name))

Sheet  Home
A1: STT | B1: Hạng mục | C1: Tên cụm | D1: Mã hoá cụm | E1: Tên địa chỉ | F1: Ký hiệu | G1: Lượng hàng | H1: Degisn_Cap (đơn vị 1000 TEU/năm)
A2: Hub Lạch Huyện - Cấp I (NĂM 2030: 3 300)
A3: 1 | B3: ICD | C3: Hải Phòng | D3: ICD1-HP | E3: ICD Tân Cảng Hải Phòng | F3: ICDHP1-1 | G3: 300 | H3: 750
E4: ICD Đình Vũ + Nam Đình Vũ | F4: ICDHP2-1 | G4: 450
A5: 2 | B5: KCN | D5: KCN1-HP | E5: VinFast Factory (FVF) | F5: KCNHP1 | G5: 101 | H5: 977
E6: Đình Vũ | F6: KCNHP2 | G6: 439
E7: Nam Đình Vũ | F7: KCNHP3 | G7: 275 | K7: CẢNG LẠCH HUYỆN
E8: DEEP C Hải phòng 3 | F8: KCNHP4 | G8: 162 | K8: ICD Tân Cảng Hải Phòng
A9: 3 | B9: Cảng sông bến thuỷ | C9: Cụm sông Cấm | D9: CS1-HP | E9: Cảng Green Port- Tư nhân | F9: CSBTSC1 | G9: 130 | H9: 800 | K9: kcn đình vũ
E10: Cảng Nam Hải | F10: CSBTSC2 | G10: 100 | K10: cụm cảng sông cấm
E11: Cảng Chùa Vẽ | F11: CSBTSC3 | G11: 160 | K11: ICD Tân Cảng Quế Võ
E12: cảng 128 | F12: CSBTSC4 | G12: 60 | K12: ICD Long Biên
E13: Cảng Hái An | F13: CSBTSC5 | G13: 270 | K13: Trung tâm Logistics Quốc tế Bắc Giang
E14: cảng Công ty TNHH MTV 189 | F14: CSBTSC6 | G14: 80 | K14: cụm kcn hà nội
A15: Trung gian vùng-Cấp II | K15: cụm kcn bắc ninh
A16: 1 | B16: ICD | C16: Bắc Ninh | D16: ICD2-BN | E16: ICD Tân Cảng Quế Võ | F16: ICDBN1 | G16: 250 | H16: 530 | K16: cụm kcn hưng yên
E17: Cảng Tân Chi (Bắc Ninh) | F17: ICDBN2 | G17: 160 | K17: 2XF9+4H3, Phú Sơn, Gia Lâm, Hà Nội
E18: ICD Tiên Sơn | F18: ICDBN3 | G18: 120 | K18: VSIP Bắc Ninh
C19: Hà Nội | D19: ICD2-HN | E19: Cảng cạn Đông Anh | F19: ICDHN1 | G19: 150 | H19: 285
E20: ICD Long Biên | F20: ICDHN2 | G20: 135
A21: 2 | B21: DC | C21: Bắc Ninh | D21: DC2-BN | E21: Trung tâm Logistics Quốc tế Bắc Giang | F21: SCTBN | G21: 280 | H21: 280
A22: 3 | B22: KCN | C22: Hà Nội (tỉ lệ xnk 40:60) tỉ trọng xuất khẩu tắng ~31%) | D22: KCN2-HN | E22: Thăng Long | F22: KCNHN1 | G22: 180 | H22: 815
E23: Nam Thăng Long | F23: KCNHN2 | G23: 13
E24: Nội Bài | F24: KCNHN3 | G24: 45
E25: Sài Đồng B | F25: KCNHN4 | G25: 127
E26: Hà Nội - Đài Tư | F26: KCNHN5 | G26: 18
E27: Thạch Thất - Quốc Oai | F27: KCNHN6 | G27: 72
E28: Phú Nghĩa | F28: KCNHN7 | G28: 360
C29: Bắc Ninh (tỉ lệ xnk 53:47) xuất siêu | D29: KCN2-BN | E29: Quế Võ I - II - III | F29: KCNBN1 | G29: 900 | H29: 3348
E30: Đại Đồng - Hoàn Sơn | F30: KCNBN2 | G30: 720
E31: Thuận Thành I - II | F31: KCNBN3 | G31: 360
E32: Tiên Sơn (GĐ1&MR) | F32: KCNBN4 | G32: 270
E33: Yên Phong I - II | F33: KCNBN5 | G33: 360
E34: VSIP- VSIP II | F34: KCNBN6 | G34: 540
E35: Gia Bình - 1 - 2 | F35: KCNBN7 | G35: 90
E36: Lương Tài 1 -2 | F36: KCNBN8 | G36: 54
E37: Yên Phong II - A | F37: KCNBN9 | G37: 54
C38: Hưng Yên (tỉ lệ xnk 52:48) ổn định xuất siêu từ 2025 | D38: KCN2-HY | E38: Phố Nối A - B | F38: KCNHY1 | G38: 720 | H38: 1251
E39: Minh Đức | F39: KCNHY2 | G39: 72
E40: Yên Mỹ - II | F40: KCNHY3 | G40: 180
...

Sheet Nodes
A1: No. | B1: Node_Name | C1: Tier | D1: Node_Type | E1: Design_Cap
A2: 1 | B2: CẢNG LẠCH HUYỆN | C2: 0 | D2: Port | E2: =3300*1000 -> 3300000
A3: 2 | B3: ICD1-HP | C3: 1 | D3: Transshipment | E3: =_xlfn.XLOOKUP(B3, ' Home'!$D$2:$D$49, ' Home'!$H$2:$H$49, "Không tìm thấy")*1000 -> 750000
A4: 3 | B4: KCN1-HP | C4: 1 | D4: Source | E4: =_xlfn.XLOOKUP(B4, ' Home'!$D$2:$D$49, ' Home'!$H$2:$H$49, "Không tìm thấy")*1000 -> 977000
A5: 4 | B5: CS1-HP | C5: 1 | D5: Transshipment | E5: =_xlfn.XLOOKUP(B5, ' Home'!$D$2:$D$49, ' Home'!$H$2:$H$49, "Không tìm thấy")*1000 -> 800000
A6: 5 | B6: ICD2-BN | C6: 2 | D6: Transshipment | E6: =_xlfn.XLOOKUP(B6, ' Home'!$D$2:$D$49, ' Home'!$H$2:$H$49, "Không tìm thấy")*1000 -> 530000
A7: 6 | B7: ICD2-HN | C7: 2 | D7: Transshipment | E7: =_xlfn.XLOOKUP(B7, ' Home'!$D$2:$D$49, ' Home'!$H$2:$H$49, "Không tìm thấy")*1000 -> 285000
A8: 7 | B8: DC2-BN | C8: 2 | D8: Sink | E8: =_xlfn.XLOOKUP(B8, ' Home'!$D$2:$D$49, ' Home'!$H$2:$H$49, "Không tìm thấy")*1000 -> 280000
A9: 8 | B9: KCN2-HN | C9: 2 | D9: Sink | E9: =_xlfn.XLOOKUP(B9, ' Home'!$D$2:$D$49, ' Home'!$H$2:$H$49, "Không tìm thấy")*1000 -> 815000
A10: 9 | B10: KCN2-BN | C10: 2 | D10: Source | E10: =_xlfn.XLOOKUP(B10, ' Home'!$D$2:$D$49, ' Home'!$H$2:$H$49, "Không tìm thấy")*1000 -> 3348000
A11: 10 | B11: KCN2-HY | C11: 2 | D11: Sink | E11: =_xlfn.XLOOKUP(B11, ' Home'!$D$2:$D$49, ' Home'!$H$2:$H$49, "Không tìm thấy")*1000 -> 1251000
A12: 11 | B12: MASAN | C12: 3 | D12: Sink | E12: =_xlfn.XLOOKUP(B12, ' Home'!$D$2:$D$49, ' Home'!$H$2:$H$49, "Không tìm thấy")*1000 -> 492000
A13: 12 | B13: AEON | C13: 3 | D13: Sink | E13: =_xlfn.XLOOKUP(B13, ' Home'!$D$2:$D$49, ' Home'!$H$2:$H$49, "Không tìm thấy")*1000 -> 20000

Sheet Cost
A1: Loại vận tải | B1: Chi phí trung bình (USD/TEU-km')
A2: Road | B2: 1
A3: Barge | B3: 0.4
A4: Rail | B4: 0.25
A6: MỨC ĐỘ 1 - BẮTBUỘC: BỔ SUNG CAPACITY (Cap_ij) | B6: Cột 1
A7: Loại tuyến | B7: Năng lực
A8: Quãng ngắn (<50km) | B8: 800000
A9: Quãng trung bình (50-150km) | B9: 500000
A10: Quãng dài (>150km) | B10: 340000
A11: Đường thuỷ | B11: 500000
A12: Đường sắt | B12: 1000000
A14: MỨC ĐỘ 1 - BẮTBUỘC: BỔ SUNG FIXED COST (FC_ij) | B14: Cột 3
A15: Loại tuyến | B15: Gợi ý cụ thể
A16: Road | B16: =1000000*6 -> 6000000
A17: Barge | B17: =1000000*20 -> 20000000
A18: Rail | B18: =1000000*80 -> 80000000

Sheet Arcs
A1: From | B1: To | C1: Mode | D1: Distance (km) | E1: UnitCost (USD/TEU-km) | F1: Cap | G1: FixedCost | H1: Enabled | I1: IsExport | J1: Note
A2: CẢNG LẠCH HUYỆN | B2: ICD1-HP | C2: Road | D2: 17 | E2: =IF(C2="","",IFERROR(INDEX(Cost!$B$2:$B$4, MATCH("*" & C2 & "*", Cost!$A$2:$A$4, 0)), "Lỗi dữ liệu")) -> 1 | F2: {=_xlfn.IFS( C2="Road",LOOKUP(D2,{0,50,150},Cost!$B$8:$B$10), C2="Barge",Cost!$B$11, C2="Rail",Cost!$B$12, TRUE,0 )} -> 800000 | G2: 0 | H2: 1 | I2: {=IF(TRIM(B2:B291)="CẢNG LẠCH HUYỆN",1,0)} -> 0
A3: CẢNG LẠCH HUYỆN | B3: ICD1-HP | C3: Barge | D3: 25 | E3: {=IF(C3="","",IFERROR(INDEX(Cost!$B$2:$B$4, MATCH("*" & C3 & "*", Cost!$A$2:$A$4, 0)), "Lỗi dữ liệu"))} -> 0.4 | F3: {=_xlfn.IFS( C3="Road",LOOKUP(D3,{0,50,150},Cost!$B$8:$B$10), C3="Barge",Cost!$B$11, C3="Rail",Cost!$B$12, TRUE,0 )} -> 500000 | G3: 0 | H3: 1 | I3: 0
A4: CẢNG LẠCH HUYỆN | B4: KCN1-HP | C4: Road | D4: 15 | E4: {=IF(C4="","",IFERROR(INDEX(Cost!$B$2:$B$4, MATCH("*" & C4 & "*", Cost!$A$2:$A$4, 0)), "Lỗi dữ liệu"))} -> 1 | F4: {=_xlfn.IFS( C4="Road",LOOKUP(D4,{0,50,150},Cost!$B$8:$B$10), C4="Barge",Cost!$B$11, C4="Rail",Cost!$B$12, TRUE,0 )} -> 800000 | G4: 0 | H4: 1 | I4: 0
A5: CẢNG LẠCH HUYỆN | B5: KCN1-HP | C5: Barge | D5: 20 | E5: {=IF(C5="","",IFERROR(INDEX(Cost!$B$2:$B$4, MATCH("*" & C5 & "*", Cost!$A$2:$A$4, 0)), "Lỗi dữ liệu"))} -> 0.4 | F5: {=_xlfn.IFS( C5="Road",LOOKUP(D5,{0,50,150},Cost!$B$8:$B$10), C5="Barge",Cost!$B$11, C5="Rail",Cost!$B$12, TRUE,0 )} -> 500000 | G5: 0 | H5: 1 | I5: 0
A6: CẢNG LẠCH HUYỆN | B6: CS1-HP | C6: Road | D6: 25 | E6: {=IF(C6="","",IFERROR(INDEX(Cost!$B$2:$B$4, MATCH("*" & C6 & "*", Cost!$A$2:$A$4, 0)), "Lỗi dữ liệu"))} -> 1 | F6: {=_xlfn.IFS( C6="Road",LOOKUP(D6,{0,50,150},Cost!$B$8:$B$10), C6="Barge",Cost!$B$11, C6="Rail",Cost!$B$12, TRUE,0 )} -> 800000 | G6: 0 | H6: 1 | I6: 0
A7: CẢNG LẠCH HUYỆN | B7: CS1-HP | C7: Barge | D7: 28 | E7: {=IF(C7="","",IFERROR(INDEX(Cost!$B$2:$B$4, MATCH("*" & C7 & "*", Cost!$A$2:$A$4, 0)), "Lỗi dữ liệu"))} -> 0.4 | F7: {=_xlfn.IFS( C7="Road",LOOKUP(D7,{0,50,150},Cost!$B$8:$B$10), C7="Barge",Cost!$B$11, C7="Rail",Cost!$B$12, TRUE,0 )} -> 500000 | G7: 0 | H7: 1 | I7: 0
A8: CẢNG LẠCH HUYỆN | B8: ICD2-BN | C8: Road | D8: 115 | E8: {=IF(C8="","",IFERROR(INDEX(Cost!$B$2:$B$4, MATCH("*" & C8 & "*", Cost!$A$2:$A$4, 0)), "Lỗi dữ liệu"))} -> 1 | F8: {=_xlfn.IFS( C8="Road",LOOKUP(D8,{0,50,150},Cost!$B$8:$B$10), C8="Barge",Cost!$B$11, C8="Rail",Cost!$B$12, TRUE,0 )} -> 500000 | G8: 0 | H8: 1 | I8: 0
A9: CẢNG LẠCH HUYỆN | B9: ICD2-BN | C9: Barge | D9: 130 | E9: {=IF(C9="","",IFERROR(INDEX(Cost!$B$2:$B$4, MATCH("*" & C9 & "*", Cost!$A$2:$A$4, 0)), "Lỗi dữ liệu"))} -> 0.4 | F9: {=_xlfn.IFS( C9="Road",LOOKUP(D9,{0,50,150},Cost!$B$8:$B$10), C9="Barge",Cost!$B$11, C9="Rail",Cost!$B$12, TRUE,0 )} -> 500000 | G9: 0 | H9: 1 | I9: 0
A10: CẢNG LẠCH HUYỆN | B10: ICD2-BN | C10: Rail | D10: 120 | E10: {=IF(C10="","",IFERROR(INDEX(Cost!$B$2:$B$4, MATCH("*" & C10 & "*", Cost!$A$2:$A$4, 0)), "Lỗi dữ liệu"))} -> 0.25 | F10: {=_xlfn.IFS( C10="Road",LOOKUP(D10,{0,50,150},Cost!$B$8:$B$10), C10="Barge",Cost!$B$11, C10="Rail",Cost!$B$12, TRUE,0 )} -> 1000000 | G10: =IF(C10="","",IFERROR(INDEX(Cost!$B$16:$B$18, MATCH("*" & C10 & "*", Cost!$A$2:$A$4, 0)), "Lỗi dữ liệu")) -> 80000000 | H10: 1 | I10: 0
A11: CẢNG LẠCH HUYỆN | B11: ICD2-HN | C11: Road | D11: 130 | E11: {=IF(C11="","",IFERROR(INDEX(Cost!$B$2:$B$4, MATCH("*" & C11 & "*", Cost!$A$2:$A$4, 0)), "Lỗi dữ liệu"))} -> 1 | F11: {=_xlfn.IFS( C11="Road",LOOKUP(D11,{0,50,150},Cost!$B$8:$B$10), C11="Barge",Cost!$B$11, C11="Rail",Cost!$B$12, TRUE,0 )} -> 500000 | G11: 0 | H11: 1 | I11: 0
A12: CẢNG LẠCH HUYỆN | B12: ICD2-HN | C12: Barge | D12: 145 | E12: {=IF(C12="","",IFERROR(INDEX(Cost!$B$2:$B$4, MATCH("*" & C12 & "*", Cost!$A$2:$A$4, 0)), "Lỗi dữ liệu"))} -> 0.4 | F12: {=_xlfn.IFS( C12="Road",LOOKUP(D12,{0,50,150},Cost!$B$8:$B$10), C12="Barge",Cost!$B$11, C12="Rail",Cost!$B$12, TRUE,0 )} -> 500000 | G12: =IF(C12="","",IFERROR(INDEX(Cost!$B$16:$B$18, MATCH("*" & C12 & "*", Cost!$A$2:$A$4, 0)), "Lỗi dữ liệu")) -> 20000000 | H12: 1 | I12: 0
A13: CẢNG LẠCH HUYỆN | B13: ICD2-HN | C13: Rail | D13: 135 | E13: {=IF(C13="","",IFERROR(INDEX(Cost!$B$2:$B$4, MATCH("*" & C13 & "*", Cost!$A$2:$A$4, 0)), "Lỗi dữ liệu"))} -> 0.25 | F13: {=_xlfn.IFS( C13="Road",LOOKUP(D13,{0,50,150},Cost!$B$8:$B$10), C13="Barge",Cost!$B$11, C13="Rail",Cost!$B$12, TRUE,0 )} -> 1000000 | G13: 5000000 | H13: 1 | I13: 0
A14: CẢNG LẠCH HUYỆN | B14: DC2-BN | C14: Road | D14: 115 | E14: {=IF(C14="","",IFERROR(INDEX(Cost!$B$2:$B$4, MATCH("*" & C14 & "*", Cost!$A$2:$A$4, 0)), "Lỗi dữ liệu"))} -> 1 | F14: {=_xlfn.IFS( C14="Road",LOOKUP(D14,{0,50,150},Cost!$B$8:$B$10), C14="Barge",Cost!$B$11, C14="Rail",Cost!$B$12, TRUE,0 )} -> 500000 | G14: 0 | H14: 1 | I14: 0
A15: CẢNG LẠCH HUYỆN | B15: DC2-BN | C15: Barge | D15: 130 | E15: {=IF(C15="","",IFERROR(INDEX(Cost!$B$2:$B$4, MATCH("*" & C15 & "*", Cost!$A$2:$A$4, 0)), "Lỗi dữ liệu"))} -> 0.4 | F15: {=_xlfn.IFS( C15="Road",LOOKUP(D15,{0,50,150},Cost!$B$8:$B$10), C15="Barge",Cost!$B$11, C15="Rail",Cost!$B$12, TRUE,0 )} -> 500000 | G15: =IF(C15="","",IFERROR(INDEX(Cost!$B$16:$B$18, MATCH("*" & C15 & "*", Cost!$A$2:$A$4, 0)), "Lỗi dữ liệu")) -> 20000000 | H15: 1 | I15: 0
A16: CẢNG LẠCH HUYỆN | B16: DC2-BN | C16: Rail | D16: 120 | E16: {=IF(C16="","",IFERROR(INDEX(Cost!$B$2:$B$4, MATCH("*" & C16 & "*", Cost!$A$2:$A$4, 0)), "Lỗi dữ liệu"))} -> 0.25 | F16: {=_xlfn.IFS( C16="Road",LOOKUP(D16,{0,50,150},Cost!$B$8:$B$10), C16="Barge",Cost!$B$11, C16="Rail",Cost!$B$12, TRUE,0 )} -> 1000000 | G16: =IF(C16="","",IFERROR(INDEX(Cost!$B$16:$B$18, MATCH("*" & C16 & "*", Cost!$A$2:$A$4, 0)), "Lỗi dữ liệu")) -> 80000000 | H16: 1 | I16: 0
A17: CẢNG LẠCH HUYỆN | B17: KCN2-HN | C17: Road | D17: 130 | E17: {=IF(C17="","",IFERROR(INDEX(Cost!$B$2:$B$4, MATCH("*" & C17 & "*", Cost!$A$2:$A$4, 0)), "Lỗi dữ liệu"))} -> 1 | F17: {=_xlfn.IFS( C17="Road",LOOKUP(D17,{0,50,150},Cost!$B$8:$B$10), C17="Barge",Cost!$B$11, C17="Rail",Cost!$B$12, TRUE,0 )} -> 500000 | G17: 0 | H17: 1 | I17: 0
A18: CẢNG LẠCH HUYỆN | B18: KCN2-HN | C18: Barge | D18: 145 | E18: {=IF(C18="","",IFERROR(INDEX(Cost!$B$2:$B$4, MATCH("*" & C18 & "*", Cost!$A$2:$A$4, 0)), "Lỗi dữ liệu"))} -> 0.4 | F18: {=_xlfn.IFS( C18="Road",LOOKUP(D18,{0,50,150},Cost!$B$8:$B$10), C18="Barge",Cost!$B$11, C18="Rail",Cost!$B$12, TRUE,0 )} -> 500000 | G18: =IF(C18="","",IFERROR(INDEX(Cost!$B$16:$B$18, MATCH("*" & C18 & "*", Cost!$A$2:$A$4, 0)), "Lỗi dữ liệu")) -> 20000000 | H18: 1 | I18: 0
A19: CẢNG LẠCH HUYỆN | B19: KCN2-HN | C19: Rail | D19: 130 | E19: {=IF(C19="","",IFERROR(INDEX(Cost!$B$2:$B$4, MATCH("*" & C19 & "*", Cost!$A$2:$A$4, 0)), "Lỗi dữ liệu"))} -> 0.25 | F19: {=_xlfn.IFS( C19="Road",LOOKUP(D19,{0,50,150},Cost!$B$8:$B$10), C19="Barge",Cost!$B$11, C19="Rail",Cost!$B$12, TRUE,0 )} -> 1000000 | G19: =IF(C19="","",IFERROR(INDEX(Cost!$B$16:$B$18, MATCH("*" & C19 & "*", Cost!$A$2:$A$4, 0)), "Lỗi dữ liệu")) -> 80000000 | H19: 1 | I19: 0
A20: CẢNG LẠCH HUYỆN | B20: KCN2-BN | C20: Road | D20: 115 | E20: {=IF(C20="","",IFERROR(INDEX(Cost!$B$2:$B$4, MATCH("*" & C20 & "*", Cost!$A$2:$A$4, 0)), "Lỗi dữ liệu"))} -> 1 | F20: {=_xlfn.IFS( C20="Road",LOOKUP(D20,{0,50,150},Cost!$B$8:$B$10), C20="Barge",Cost!$B$11, C20="Rail",Cost!$B$12, TRUE,0 )} -> 500000 | G20: 0 | H20: 1 | I20: 0
A21: CẢNG LẠCH HUYỆN | B21: KCN2-BN | C21: Rail | D21: 120 | E21: {=IF(C21="","",IFERROR(INDEX(Cost!$B$2:$B$4, MATCH("*" & C21 & "*", Cost!$A$2:$A$4, 0)), "Lỗi dữ liệu"))} -> 0.25 | F21: {=_xlfn.IFS( C21="Road",LOOKUP(D21,{0,50,150},Cost!$B$8:$B$10), C21="Barge",Cost!$B$11, C21="Rail",Cost!$B$12, TRUE,0 )} -> 1000000 | G21: =IF(C21="","",IFERROR(INDEX(Cost!$B$16:$B$18, MATCH("*" & C21 & "*", Cost!$A$2:$A$4, 0)), "Lỗi dữ liệu")) -> 80000000 | H21: 1 | I21: 0
A22: CẢNG LẠCH HUYỆN | B22: KCN2-HY | C22: Road | D22: 110 | E22: {=IF(C22="","",IFERROR(INDEX(Cost!$B$2:$B$4, MATCH("*" & C22 & "*", Cost!$A$2:$A$4, 0)), "Lỗi dữ liệu"))} -> 1 | F22: {=_xlfn.IFS( C22="Road",LOOKUP(D22,{0,50,150},Cost!$B$8:$B$10), C22="Barge",Cost!$B$11, C22="Rail",Cost!$B$12, TRUE,0 )} -> 500000 | G22: 0 | H22: 1 | I22: 0
A23: CẢNG LẠCH HUYỆN | B23: KCN2-HY | C23: Barge | D23: 125 | E23: {=IF(C23="","",IFERROR(INDEX(Cost!$B$2:$B$4, MATCH("*" & C23 & "*", Cost!$A$2:$A$4, 0)), "Lỗi dữ liệu"))} -> 0.4 | F23: {=_xlfn.IFS( C23="Road",LOOKUP(D23,{0,50,150},Cost!$B$8:$B$10), C23="Barge",Cost!$B$11, C23="Rail",Cost!$B$12, TRUE,0 )} -> 500000 | G23: =IF(C23="","",IFERROR(INDEX(Cost!$B$16:$B$18, MATCH("*" & C23 & "*", Cost!$A$2:$A$4, 0)), "Lỗi dữ liệu")) -> 20000000 | H23: 1 | I23: 0
A24: CẢNG LẠCH HUYỆN | B24: MASAN | C24: Road | D24: 120 | E24: {=IF(C24="","",IFERROR(INDEX(Cost!$B$2:$B$4, MATCH("*" & C24 & "*", Cost!$A$2:$A$4, 0)), "Lỗi dữ liệu"))} -> 1 | F24: {=_xlfn.IFS( C24="Road",LOOKUP(D24,{0,50,150},Cost!$B$8:$B$10), C24="Barge",Cost!$B$11, C24="Rail",Cost!$B$12, TRUE,0 )} -> 500000 | G24: 0 | H24: 1 | I24: 0
A25: CẢNG LẠCH HUYỆN | B25: MASAN | C25: Barge | D25: 135 | E25: {=IF(C25="","",IFERROR(INDEX(Cost!$B$2:$B$4, MATCH("*" & C25 & "*", Cost!$A$2:$A$4, 0)), "Lỗi dữ liệu"))} -> 0.4 | F25: {=_xlfn.IFS( C25="Road",LOOKUP(D25,{0,50,150},Cost!$B$8:$B$10), C25="Barge",Cost!$B$11, C25="Rail",Cost!$B$12, TRUE,0 )} -> 500000 | G25: =IF(C25="","",IFERROR(INDEX(Cost!$B$16:$B$18, MATCH("*" & C25 & "*", Cost!$A$2:$A$4, 0)), "Lỗi dữ liệu")) -> 20000000 | H25: 1 | I25: 0
A26: CẢNG LẠCH HUYỆN | B26: MASAN | C26: Rail | D26: 125 | E26: {=IF(C26="","",IFERROR(INDEX(Cost!$B$2:$B$4, MATCH("*" & C26 & "*", Cost!$A$2:$A$4, 0)), "Lỗi dữ liệu"))} -> 0.25 | F26: {=_xlfn.IFS( C26="Road",LOOKUP(D26,{0,50,150},Cost!$B$8:$B$10), C26="Barge",Cost!$B$11, C26="Rail",Cost!$B$12, TRUE,0 )} -> 1000000 | G26: =IF(C26="","",IFERROR(INDEX(Cost!$B$16:$B$18, MATCH("*" & C26 & "*", Cost!$A$2:$A$4, 0)), "Lỗi dữ liệu")) -> 80000000 | H26: 1 | I26: 0
A27: CẢNG LẠCH HUYỆN | B27: AEON | C27: Road | D27: 125 | E27: {=IF(C27="","",IFERROR(INDEX(Cost!$B$2:$B$4, MATCH("*" & C27 & "*", Cost!$A$2:$A$4, 0)), "Lỗi dữ liệu"))} -> 1 | F27: {=_xlfn.IFS( C27="Road",LOOKUP(D27,{0,50,150},Cost!$B$8:$B$10), C27="Barge",Cost!$B$11, C27="Rail",Cost!$B$12, TRUE,0 )} -> 500000 | G27: =IF(C27="","",IFERROR(INDEX(Cost!$B$16:$B$18, MATCH("*" & C27 & "*", Cost!$A$2:$A$4, 0)), "Lỗi dữ liệu")) -> 6000000 | H27: 1 | I27: 0
A28: CẢNG LẠCH HUYỆN | B28: AEON | C28: Barge | D28: 140 | E28: {=IF(C28="","",IFERROR(INDEX(Cost!$B$2:$B$4, MATCH("*" & C28 & "*", Cost!$A$2:$A$4, 0)), "Lỗi dữ liệu"))} -> 0.4 | F28: {=_xlfn.IFS( C28="Road",LOOKUP(D28,{0,50,150},Cost!$B$8:$B$10), C28="Barge",Cost!$B$11, C28="Rail",Cost!$B$12, TRUE,0 )} -> 500000 | G28: =IF(C28="","",IFERROR(INDEX(Cost!$B$16:$B$18, MATCH("*" & C28 & "*", Cost!$A$2:$A$4, 0)), "Lỗi dữ liệu")) -> 20000000 | H28: 1 | I28: 0
A29: CẢNG LẠCH HUYỆN | B29: AEON | C29: Rail | D29: 130 | E29: {=IF(C29="","",IFERROR(INDEX(Cost!$B$2:$B$4, MATCH("*" & C29 & "*", Cost!$A$2:$A$4, 0)), "Lỗi dữ liệu"))} -> 0.25 | F29: {=_xlfn.IFS( C29="Road",LOOKUP(D29,{0,50,150},Cost!$B$8:$B$10), C29="Barge",Cost!$B$11, C29="Rail",Cost!$B$12, TRUE,0 )} -> 1000000 | G29: =IF(C29="","",IFERROR(INDEX(Cost!$B$16:$B$18, MATCH("*" & C29 & "*", Cost!$A$2:$A$4, 0)), "Lỗi dữ liệu")) -> 80000000 | H29: 1 | I29: 0
A30: ICD1-HP | B30: CẢNG LẠCH HUYỆN | C30: Road | D30: 35 | E30: {=IF(C30="","",IFERROR(INDEX(Cost!$B$2:$B$4, MATCH("*" & C30 & "*", Cost!$A$2:$A$4, 0)), "Lỗi dữ liệu"))} -> 1 | F30: {=_xlfn.IFS( C30="Road",LOOKUP(D30,{0,50,150},Cost!$B$8:$B$10), C30="Barge",Cost!$B$11, C30="Rail",Cost!$B$12, TRUE,0 )} -> 800000 | G30: 0 | H30: 1 | I30: 1
A31: ICD1-HP | B31: CẢNG LẠCH HUYỆN | C31: Barge | D31: 40 | E31: {=IF(C31="","",IFERROR(INDEX(Cost!$B$2:$B$4, MATCH("*" & C31 & "*", Cost!$A$2:$A$4, 0)), "Lỗi dữ liệu"))} -> 0.4 | F31: {=_xlfn.IFS( C31="Road",LOOKUP(D31,{0,50,150},Cost!$B$8:$B$10), C31="Barge",Cost!$B$11, C31="Rail",Cost!$B$12, TRUE,0 )} -> 500000 | G31: =IF(C31="","",IFERROR(INDEX(Cost!$B$16:$B$18, MATCH("*" & C31 & "*", Cost!$A$2:$A$4, 0)), "Lỗi dữ liệu")) -> 20000000 | H31: 1 | I31: 1
A32: ICD1-HP | B32: KCN1-HP | C32: Road | D32: 15 | E32: {=IF(C32="","",IFERROR(INDEX(Cost!$B$2:$B$4, MATCH("*" & C32 & "*", Cost!$A$2:$A$4, 0)), "Lỗi dữ liệu"))} -> 1 | F32: {=_xlfn.IFS( C32="Road",LOOKUP(D32,{0,50,150},Cost!$B$8:$B$10), C32="Barge",Cost!$B$11, C32="Rail",Cost!$B$12, TRUE,0 )} -> 800000 | G32: 0 | H32: 1 | I32: 0
A33: ICD1-HP | B33: KCN1-HP | C33: Barge | D33: 50 | E33: {=IF(C33="","",IFERROR(INDEX(Cost!$B$2:$B$4, MATCH("*" & C33 & "*", Cost!$A$2:$A$4, 0)), "Lỗi dữ liệu"))} -> 0.4 | F33: {=_xlfn.IFS( C33="Road",LOOKUP(D33,{0,50,150},Cost!$B$8:$B$10), C33="Barge",Cost!$B$11, C33="Rail",Cost!$B$12, TRUE,0 )} -> 500000 | G33: =IF(C33="","",IFERROR(INDEX(Cost!$B$16:$B$18, MATCH("*" & C33 & "*", Cost!$A$2:$A$4, 0)), "Lỗi dữ liệu")) -> 20000000 | H33: 1 | I33: 0
A34: ICD1-HP | B34: KCN1-HP | C34: Rail | D34: 120 | E34: {=IF(C34="","",IFERROR(INDEX(Cost!$B$2:$B$4, MATCH("*" & C34 & "*", Cost!$A$2:$A$4, 0)), "Lỗi dữ liệu"))} -> 0.25 | F34: {=_xlfn.IFS( C34="Road",LOOKUP(D34,{0,50,150},Cost!$B$8:$B$10), C34="Barge",Cost!$B$11, C34="Rail",Cost!$B$12, TRUE,0 )} -> 1000000 | G34: =IF(C34="","",IFERROR(INDEX(Cost!$B$16:$B$18, MATCH("*" & C34 & "*", Cost!$A$2:$A$4, 0)), "Lỗi dữ liệu")) -> 80000000 | H34: 1 | I34: 0
A35: ICD1-HP | B35: CS1-HP | C35: Road | D35: 10 | E35: {=IF(C35="","",IFERROR(INDEX(Cost!$B$2:$B$4, MATCH("*" & C35 & "*", Cost!$A$2:$A$4, 0)), "Lỗi dữ liệu"))} -> 1 | F35: {=_xlfn.IFS( C35="Road",LOOKUP(D35,{0,50,150},Cost!$B$8:$B$10), C35="Barge",Cost!$B$11, C35="Rail",Cost!$B$12, TRUE,0 )} -> 800000 | G35: 0 | H35: 1 | I35: 0
A36: ICD1-HP | B36: CS1-HP | C36: Barge | D36: 15 | E36: {=IF(C36="","",IFERROR(INDEX(Cost!$B$2:$B$4, MATCH("*" & C36 & "*", Cost!$A$2:$A$4, 0)), "Lỗi dữ liệu"))} -> 0.4 | F36: {=_xlfn.IFS( C36="Road",LOOKUP(D36,{0,50,150},Cost!$B$8:$B$10), C36="Barge",Cost!$B$11, C36="Rail",Cost!$B$12, TRUE,0 )} -> 500000 | G36: =IF(C36="","",IFERROR(INDEX(Cost!$B$16:$B$18, MATCH("*" & C36 & "*", Cost!$A$2:$A$4, 0)), "Lỗi dữ liệu")) -> 20000000 | H36: 1 | I36: 0
A37: ICD1-HP | B37: ICD2-BN | C37: Road | D37: 110 | E37: {=IF(C37="","",IFERROR(INDEX(Cost!$B$2:$B$4, MATCH("*" & C37 & "*", Cost!$A$2:$A$4, 0)), "Lỗi dữ liệu"))} -> 1 | F37: {=_xlfn.IFS( C37="Road",LOOKUP(D37,{0,50,150},Cost!$B$8:$B$10), C37="Barge",Cost!$B$11, C37="Rail",Cost!$B$12, TRUE,0 )} -> 500000 | G37: =IF(C37="","",IFERROR(INDEX(Cost!$B$16:$B$18, MATCH("*" & C37 & "*", Cost!$A$2:$A$4, 0)), "Lỗi dữ liệu")) -> 6000000 | H37: 1 | I37: 0
A38: ICD1-HP | B38: ICD2-BN | C38: Barge | D38: 120 | E38: {=IF(C38="","",IFERROR(INDEX(Cost!$B$2:$B$4, MATCH("*" & C38 & "*", Cost!$A$2:$A$4, 0)), "Lỗi dữ liệu"))} -> 0.4 | F38: {=_xlfn.IFS( C38="Road",LOOKUP(D38,{0,50,150},Cost!$B$8:$B$10), C38="Barge",Cost!$B$11, C38="Rail",Cost!$B$12, TRUE,0 )} -> 500000 | G38: =IF(C38="","",IFERROR(INDEX(Cost!$B$16:$B$18, MATCH("*" & C38 & "*", Cost!$A$2:$A$4, 0)), "Lỗi dữ liệu")) -> 20000000 | H38: 1 | I38: 0
A39: ICD1-HP | B39: ICD2-BN | C39: Rail | D39: 115 | E39: {=IF(C39="","",IFERROR(INDEX(Cost!$B$2:$B$4, MATCH("*" & C39 & "*", Cost!$A$2:$A$4, 0)), "Lỗi dữ liệu"))} -> 0.25 | F39: {=_xlfn.IFS( C39="Road",LOOKUP(D39,{0,50,150},Cost!$B$8:$B$10), C39="Barge",Cost!$B$11, C39="Rail",Cost!$B$12, TRUE,0 )} -> 1000000 | G39: =IF(C39="","",IFERROR(INDEX(Cost!$B$16:$B$18, MATCH("*" & C39 & "*", Cost!$A$2:$A$4, 0)), "Lỗi dữ liệu")) -> 80000000 | H39: 1 | I39: 0
A40: ICD1-HP | B40: ICD2-HN | C40: Road | D40: 120 | E40: {=IF(C40="","",IFERROR(INDEX(Cost!$B$2:$B$4, MATCH("*" & C40 & "*", Cost!$A$2:$A$4, 0)), "Lỗi dữ liệu"))} -> 1 | F40: {=_xlfn.IFS( C40="Road",LOOKUP(D40,{0,50,150},Cost!$B$8:$B$10), C40="Barge",Cost!$B$11, C40="Rail",Cost!$B$12, TRUE,0 )} -> 500000 | G40: =IF(C40="","",IFERROR(INDEX(Cost!$B$16:$B$18, MATCH("*" & C40 & "*", Cost!$A$2:$A$4, 0)), "Lỗi dữ liệu")) -> 6000000 | H40: 1 | I40: 0
...

Sheet Supply
A1: IP | B1: Supply
A2: CẢNG LẠCH HUYỆN | B2: 1300 | C2: (Đơn vị: 1000 TEU)
A3: KCN2-BN | B3: 2000
A4: KCN1-HP | B4: 700

Sheet Demand
A1: DC | B1: Demand
A2: DC2-BN | B2: 280 | C2: (Đơn vị: 1000 TEU)
A3: KCN2-HN | B3: 480
A4: KCN2-HY | B4: 900
A5: MASAN | B5: 400
A6: AEON | B6: 5

Sheet Params
A1: Key | B1: Value
A2: exportDemand | B2: =(SUM(Supply!B2:B100) - SUMIF(Demand!A2:A100, "<>*CẢNG LẠCH HUYỆN*", Demand!B2:B100))*1000 -> 1935000
A3: BigM | B3: 5000000
A4: KL | B4: 1000000000
A5: KICD | B5: 1000000000
A6: KPORT | B6: 1000000000
A7: hL | B7: 8
A8: hICD | B8: 10
A9: hPORT | B9: 6
A10: K_road | B10: Inf
A11: K_rail | B11: Inf
A12: K_water | B12: Inf
A13: K_sea | B13: Inf
A14: EF_road | B14: 0.12
A15: EF_rail | B15: 0.05
A16: EF_barge | B16: 0.03
A17: EF_sea | B17: 0.02
A18: Emax
A19: lambdaCO2 | B19: 1
A20: TimeLimit | B20: 10

Sheet Cách giả định Cap
A1: Từ các nghiên cứu về hub logistics và relay networks:
A3: Nếu bạn có dữ liệu đội xe và kế hoạch khai thác, có thể đặt:
A4: Sức chứa tuyến i–j (TEU/ngày) = (số chuyến/ngày trên i–j) × (TEU/trip)
A5: Nếu chưa có số liệu chi tiết đội xe:
A6: Dùng “công suất thiết kế” của tuyến dựa trên: năng lực cảng/hub liên quan và mức sử dụng mong muốn (ví dụ 70–80% để tránh tắc nghẽn), giống các mô hình capacity deployment 3457+1 MORE.
A7: Trong mô hình MIP, bạn có thể:
A8: Đặt giới hạn luồng trên arc bằng biến số xe × tải trọng, với số xe bị giới hạn bởi chi phí/hợp đồng;
A9: Hoặc dùng ngưỡng cố định rút ra từ tổng công suất hub chia cho số tuyến kết nối, rồi kiểm tra độ nhạy (sensitivity analysis), cách làm phổ biến trong các bài toán hub logistics
